Workbook

Sheet Release Notes
A1: Date | B1: Version | C1: Update
A2: 46045 | B2: 1 | C2: Initial version
A3: 46048 | B3: 1.1 | C3: Add Extended Memory pricing for VM Add Yearly archives data in backup estimation

Sheet Summary
A1: GKE
B3: Nb VM | D3: Target in GCP
A4: Kubernetes Worker Node | B4: ='VMware Inventory'!H1-'VMware Inventory'!I1 -> 66 | D4: GKE
A5: Kubernetes Control Plane | B5: ='VMware Inventory'!I1 -> 21 | D5: No Lift & Shift
A7: TOTAL | B7: =sum(B4:B6) -> 87
A9: VM Infra.
A11: Current Environment | B11: # Existing Server | C11: Migration Type | D11: Target in Google Cloud | E11: # VM at the target
A12: NSX-T Manager | B12: ='Infra Study'!D1 -> 3 | C12: No Lift & Shift | D12: GCP Infrastructure | E12: 0
A13: Storage & Backup (VxRail, VSAN, vCenter, VEEAM) | B13: ='Infra Study'!C1 -> 98 | C13: No Lift & Shift | D13: Google Cloud Backup & DR | E13: 0
A14: Firewall OpenSense | B14: ='Infra Study'!E1 -> 4 | C14: Lift & Shift Production | D14: Firewall OpenSense | E14: =B14 -> 4
A15: DHCP Server | B15: ='Infra Study'!B1 -> 23 | C15: No Lift & Shift | D15: VPC | E15: 0
A16: WSUS Server | B16: ='Infra Study'!F1 -> 13 | C16: No Lift & Shift | D16: VMManager | E16: 0
A17: Bastion Server | B17: ='Infra Study'!H1 -> 12 | C17: Lift & Shift Production | D17: Bastion Server | E17: =B17 -> 12
A18: SMTP Server | B18: ='Infra Study'!G1 -> 13 | C18: Consolidation | D18: SMTP Server | E18: 2
A19: DNS Server | B19: ='Infra Study'!I1 -> 2 | C19: No Lift & Shift | D19: Cloud DNS | E19: 0
A20: Active Directory | B20: ='Infra Study'!K1 -> 38 | C20: Consolidation | D20: AD Consolidation | E20: 12
A21: Fortinet Server | B21: ='Infra Study'!J1 -> 7 | C21: Lift & Shift Production | D21: Fortinet Server | E21: =B21 -> 7
A22: Virtual Desktop Infrastructure | B22: ='Infra Study'!L1 -> 200 | C22: Consolidation | D22: Windows Server | E22: 21
A24: TOTAL | B24: =SUM(B12:B23) -> 413 | E24: =SUM(E12:E23) -> 58
A26: Migration Path
A28: VM Type | B28: Total # Existing Server | C28: # Existing Server | D28: Migration Type | E28: # Target Server | F28: Total # Target Server | G28: Remark
A29: Infrastructure VM | B29: =sum(C29:C31) -> 413 | C29: =sum(B12,B13,B15,B16,B19) -> 139 | D29: No Lift & Shift | E29: 0 | F29: =sum(E29:E31) -> 41 | G29: Veeam, DHCP, Vmware, WSUS
C30: =B18+B20+B22 -> 251 | D30: Consolidation | E30: =E18+E20+E22 -> 35 | G30: Active Directory, SMTP, VDI
C31: =B14+B17+B21 -> 23 | D31: Lift & Shift Production | E31: =Pivot!B65 -> 6 | G31: Bastion, Fortinet
A32: Application VM | B32: =sum(C32:C34) -> 1112 | C32: =Pivot!B144 -> 157 | D32: No Lift & Shift | E32: 0 | F32: =sum(E32:E34) -> 955 | G32: Old OS (32bits, Windows 2008R2)
C33: =Pivot!B143 -> 759 | D33: Lift & Shift Production | E33: =C33 -> 759
C34: =Pivot!B142 -> 196 | D34: Lift & Shift No Production | E34: =C34 -> 196
A35: Kubernetes | B35: =sum(C35:C36) -> 87 | C35: =B4 -> 66 | D35: GKE | E35: =C35 -> 66 | F35: =sum(E35:E36) -> 66 | G35: Migrate to Google Kubernetes Engine
C36: =B5 -> 21 | D36: No Lift & Shift | E36: 0 | G36: Existing master node
A37: File Server | B37: =sum(C37) -> 23 | C37: ='GCNV Pricing'!A27 -> 23 | D37: GCNV | E37: 0 | F37: =sum(E37) -> 0 | G37: Migrate to Google Cloud Netapp Volume
A39: Total | B39: =sum(B29:B37) -> 1635 | C39: =sum(C29:C37) -> 1635 | E39: =sum(E29:E36) -> 1062 | F39: =sum(F29:F36) -> 1062
A41: Application
A43: Environment | B43: Application | C43: Machine Type | D43: Disk Type | E43: # VM
A44: Non Production | B44: All | C44: E2 | D44: Balanced | E44: =E34 -> 196
A45: Production | B45: Kalisil & Tier 1 | C45: N4 | D45: Hyperdisk Balanced | E45: =Pivot!B150
B46: Critical & Tier 1 | C46: N2D | D46: Regional SSD | E46: =Pivot!C159 -> 353
B47: Critical & Tier 2 / 3 | C47: N2D | D47: SSD | E47: =Pivot!C160+Pivot!C161 -> 134 | G47: Cloud Storage DRP Kalisil FRONT
B48: Standard & Tier 1 | C48: N2D | D48: Regional Balanced | E48: =Pivot!C155 -> 11 | G48: 1679.36
B49: Standard & Tier 2 / 3 / N/A | C49: N2D | D49: Balanced | E49: =Pivot!C156+Pivot!C157+Pivot!C154 -> 261 | G49: BDD Small VMs
G50: 1435.65
...

Sheet VMware Inventory
A1: =COUNTA(A3:A1614) -> 1612 | C1: =sum(C3:C1614) -> 14 | G1: =sum(G3:G1614) -> 1265 | H1: =sum(H3:H1614) -> 87 | I1: =sum(I3:I1614) -> 21 | J1: =sum(J3:J1614) -> 413 | K1: =sum(K3:K1614) -> 0 | L1: =sum(L3:L1614) -> 32 | N1: =sum(N3:N1614) -> 129 | P1: =sum(P3:P1614) -> 939 | Q1: =sum(Q3:Q1614) -> 8952 | R1: =sum(R3:R1614) -> 30592 | S1: =sum(S3:S1614) -> 2068228 | U1: =sum(U3:U1614) -> 962 | W1: =sum(W3:W1614) -> 4479 | X1: =sum(X3:X1614) -> 13833 | Z1: =sum(Z3:Z1614) -> 697354 | AF1: =sum(AF3:AF1614) -> 65637.754 | AH1: =sum(AH3:AH1614) -> 88258.904 | AN1: =sum(AN3:AN1614) -> 112768.99 | AO1: =sum(AO3:AO1614) -> 266665.65 | AQ1: =sum(AQ3:AQ1614) -> 1836.3
A2: VM Name | B2: OS Name | C2: 32-bit | D2: OS Type | E2: OS | F2: OS Version | G2: Prod Env. | H2: K8S Worker Node | I2: K8S Master | J2: VM Infra | K2: File Server | L2: Old OS | M2: Application Group | N2: Kalisil? | O2: Application Tiering | P2: App Criticity | Q2: vCPU | R2: RAM (GiB) | S2: Disk (GiB) | T2: Target | U2: Lift & Shift? | V2: VM Machine Type | W2: VM vCPU | X2: VM RAM | Y2: Extended Memory? | Z2: VM Disk | AA2: VM Pricing Type | AB2: VM vCPU SKU | AC2: VM RAM SKU | AD2: VM Extended RAM | AE2: VM Up Time | AF2: Compute Monthly Pricing | AG2: VM OS SKU | AH2: OS Pricing | AI2: VM DIsk Scope | AJ2: VM Disk Type | AK2: VM DIsk SKU | AL2: VM Disk IOPS | AM2: VM Disk Throughput | AN2: Disk Pricing | AO2: Total VM Monthly Pricing | AP2: VM Manager SKU | AQ2: VM Manager Monthly Pricing | AR2: Kalisil Rep
A3: VMPROJETUNI | B3: =ifna(if(vlookup(A3,vOS!A:B,2,0)="","Unknown",vlookup(A3,vOS!A:B,2,0)),"Unknown") -> Microsoft Windows Server 2012 (64-bit) | C3: =vlookup(B3,'OS Study'!A:D,2,0) -> 0 | D3: =vlookup(B3,'OS Study'!A:D,3,0) -> Windows | E3: =vlookup(B3,'OS Study'!A:D,4,0) -> Server | F3: =vlookup(B3,'OS Study'!A:E,5,0) -> 2012 | G3: =IF(vlookup(A3,'RVtools V2.1'!A:J,4,0)="non",0,1) -> 0 | H3: =if(vlookup(A3,'RVtools V2.1'!A:K,11,0)="kube",1,0) -> 0 | I3: =if(H3=1, IF(COUNTIF(A3, "*MASTER*"), 1, 0),0) -> 0 | J3: =ifna(vlookup(A3,'Infra Study'!A:Q,17,0),0) -> 0 | K3: =IFERROR(__xludf.DUMMYFUNCTION("N(REGEXMATCH(VLOOKUP(A3, 'RVtools V2.1'!A:H, 8, 0), ""^Serveur de fichiers""))"),0.0) -> 0 | L3: =if(OR(C3=1,F3="2008 R2"),1,0) -> 0 | M3: =ifna(vlookup(A3,'RVtools V2.1'!A:I,8,0),"N/A") -> Ancien Serveur Web Incomplet | N3: =IFERROR(__xludf.DUMMYFUNCTION("IF(REGEXMATCH(M3, ""(?i)"" & JOIN(""|"", SPLIT(""kalisil"", "" ""))), 1, 0)"),0.0) -> 0 | O3: =vlookup(A3,'RVtools V2.1'!A:H,7,0) -> N/A | P3: =if(vlookup(A3,'RVtools V2.1'!A:H,5,0)="oui",1,0) -> 0 | Q3: =ifna(vlookup(A3,vCPU!A:B,2,0),"Unknown") -> 2 | R3: =ifna(vlookup(A3,vMemory!A:C,3,0),"Unknown") -> 4 | S3: =ifna(vlookup(A3,vDisk!A:C,3,0),"Unknown") -> 101 | T3: {=IFS( L3=1, "No Lift & Shift", J3=1, XLOOKUP(A3, 'Infra Study'!A:A, 'Infra Study'!P:P), I3=1, "No Lift & Shift", H3=1, "GKE", K3=1, "GCNV", G3=1, "Lift & Shift Prod", TRUE, "Lift & Shift Noprod" )} -> Lift & Shift Noprod | U3: =if(OR(T3="Lift & Shift Prod", T3="Lift & Shift Noprod"),1,0) -> 1 | V3: =if(T3="Lift & Shift Noprod",if( Y3=0,Assumptions!$B$5, Assumptions!$B$4),if(T3="Lift & Shift Prod",if(AND(N3=1,O3="T1"),Assumptions!$B$6,Assumptions!$B$4),0)) -> E2 | W3: =if(V3<>0,if(Q3="Unknown", Assumptions!$B$42,If(Q3>1,Q3,2)),0) -> 2 | X3: =if(V3<>0,if(R3="Unknown", Assumptions!$B$43,R3),0) -> 4 | Y3: =if(U3=1,if(X3/W3>8,1,0),0) -> 0 | Z3: =if(V3<>0,if( S3="Unknown", Assumptions!$B$44,S3),0) -> 101 | AA3: =if(V3 ="N2",ifna(vlookup(W3&"-"&X3,'Ref. VM'!A:B,2,0),"Custom"),if(V3 ="E2" , ifna(vlookup(W3&"-"&X3,'Ref. VM'!D:E,2,0),"Custom"),if(V3="N2D",ifna(vlookup(W3&"-"&X3,'Ref. VM'!G:H,2,0),"Custom"),if(V3="N4",ifna(vlookup(W3&"-"&X3,'Ref. VM'!J:K,2,0),"Custom"),0)))) -> Custom | AB3: =if( V3<>0,if(T3="Lift & Shift Prod",V3&"-"&AA3&" vCPUs-"&"CUD 3y",V3&"-"&AA3&" vCPUs"),0) -> E2-Custom vCPUs | AC3: =if( V3<>0,if(T3="Lift & Shift Prod",V3&"-"&AA3&" RAM-"&"CUD 3y",V3&"-"&AA3&" RAM"),0) -> E2-Custom RAM | AD3: =if(Y3=0,0,if( V3="N2D",if(T3="Lift & Shift Noprod","N2D-Extended custom memory","N2D-Extended custom memory-CUD 3y"),"N4-Extended custom memory")) -> 0 | AE3: =if(T3="Lift & Shift Prod",730,if(T3="Lift & Shift Noprod",Assumptions!$B$3,0)) -> 270 | AF3: =if( U3=0,0,if(Y3=0, ((vlookup(AB3,'SKU Pricing'!A:B,Assumptions!$B$2,0)*W3)+(vlookup(AC3,'SKU Pricing'!A:B,Assumptions!$B$2,0)*X3))*AE3,((vlookup(AB3,'SKU Pricing'!A:B,Assumptions!$B$2,0)*W3)+(vlookup(AC3,'SKU Pricing'!A:B,Assumptions!$B$2,0)*(W3*8))+(vlookup(AD3,'SKU Pricing'!A:B,Assumptions!$B$2,0)*(X3-(W3*8))))*AE3)) -> 18.191628 | AG3: =if(V3<>0, if(D3="Windows","Windows Server",if(D3="Linux",if( E3="Red Hat",if( W3<=8,"Red Hat Enterprise Linux 2-8", if(W3<128,"Red Hat Enterprise Linux 9-127","Red Hat Enterprise Linux 128")),0),0)),0) -> Windows Server | AH3: =ifna(vlookup(AG3,'SKU Pricing'!A:B,Assumptions!$B$2,0)*W3*AE3,0) -> 24.84 | AI3: =if(V3<>0, if(O3="T1","Regional",""),"") | AJ3: =if(V3<>0, if(T3="Lift & Shift Noprod",Assumptions!$B$9,if(V3=Assumptions!$B$6,Assumptions!$B$10,if(P3=1,Assumptions!$B$8,Assumptions!$B$7))),"") -> Balanced | AK3: =if( AJ3="",0,if(AI3="",AJ3,AJ3)) -> Balanced | AL3: =if(AJ3="Hyperdisk Balanced",Assumptions!$B$11,0) -> 0 | AM3: =if(AJ3="Hyperdisk Balanced",Assumptions!$B$12,0) -> 0 | AN3: =if(AK3=0,0,if(AJ3="Hyperdisk Balanced",vlookup(AK3&" provisioned space",'SKU Pricing'!A:B,Assumptions!$B$2,0)*Z3+vlookup(AK3&" provisioned IOPS",'SKU Pricing'!A:B,Assumptions!$B$2,0)*AL3*730+vlookup(AK3&" provisioned throughput",'SKU Pricing'!A:B,Assumptions!$B$2,0)*AM3*730,vlookup(AK3,'SKU Pricing'!A:B,Assumptions!$B$2,0)*Z3)) -> 11.716 | AO3: =AF3+AH3+AN3 -> 54.747628 | AP3: =if(V3<>0, "VM Manager",0) -> VM Manager | AQ3: =ifna(vlookup(AP3,'SKU Pricing'!A:B,Assumptions!$B$2,0)*AE3,0) -> 0.81 | AR3: 0
A4: vmShadoc_Mirialis | B4: =ifna(if(vlookup(A4,vOS!A:B,2,0)="","Unknown",vlookup(A4,vOS!A:B,2,0)),"Unknown") -> Debian GNU/Linux 9 (64-bit) | C4: =vlookup(B4,'OS Study'!A:D,2,0) -> 0 | D4: =vlookup(B4,'OS Study'!A:D,3,0) -> Linux | E4: =vlookup(B4,'OS Study'!A:D,4,0) -> Debian | F4: =vlookup(B4,'OS Study'!A:E,5,0) -> 9 | G4: =IF(vlookup(A4,'RVtools V2.1'!A:J,4,0)="non",0,1) -> 1 | H4: =if(vlookup(A4,'RVtools V2.1'!A:K,11,0)="kube",1,0) -> 0 | I4: =if(H4=1, IF(COUNTIF(A4, "*MASTER*"), 1, 0),0) -> 0 | J4: =ifna(vlookup(A4,'Infra Study'!A:Q,17,0),0) -> 0 | K4: =IFERROR(__xludf.DUMMYFUNCTION("N(REGEXMATCH(VLOOKUP(A4, 'RVtools V2.1'!A:H, 8, 0), ""^Serveur de fichiers""))"),0.0) -> 0 | L4: =if(OR(C4=1,F4="2008 R2"),1,0) -> 0 | M4: =ifna(vlookup(A4,'RVtools V2.1'!A:I,8,0),"N/A") -> Base de donnée Ancien CLARILAB MIRIALIS | N4: =IFERROR(__xludf.DUMMYFUNCTION("IF(REGEXMATCH(M4, ""(?i)"" & JOIN(""|"", SPLIT(""kalisil"", "" ""))), 1, 0)"),0.0) -> 0 | O4: =vlookup(A4,'RVtools V2.1'!A:H,7,0) -> T3 | P4: =if(vlookup(A4,'RVtools V2.1'!A:H,5,0)="oui",1,0) -> 0 | Q4: =ifna(vlookup(A4,vCPU!A:B,2,0),"Unknown") -> 1 | R4: =ifna(vlookup(A4,vMemory!A:C,3,0),"Unknown") -> 4 | S4: =ifna(vlookup(A4,vDisk!A:C,3,0),"Unknown") -> 5393 | T4: {=IFS( L4=1, "No Lift & Shift", J4=1, XLOOKUP(A4, 'Infra Study'!A:A, 'Infra Study'!P:P), I4=1, "No Lift & Shift", H4=1, "GKE", K4=1, "GCNV", G4=1, "Lift & Shift Prod", TRUE, "Lift & Shift Noprod" )} -> Lift & Shift Prod | U4: =if(OR(T4="Lift & Shift Prod", T4="Lift & Shift Noprod"),1,0) -> 1 | V4: =if(T4="Lift & Shift Noprod",if( Y4=0,Assumptions!$B$5, Assumptions!$B$4),if(T4="Lift & Shift Prod",if(AND(N4=1,O4="T1"),Assumptions!$B$6,Assumptions!$B$4),0)) -> N2D | W4: =if(V4<>0,if(Q4="Unknown", Assumptions!$B$42,If(Q4>1,Q4,2)),0) -> 2 | X4: =if(V4<>0,if(R4="Unknown", Assumptions!$B$43,R4),0) -> 4 | Y4: =if(U4=1,if(X4/W4>8,1,0),0) -> 0 | Z4: =if(V4<>0,if( S4="Unknown", Assumptions!$B$44,S4),0) -> 5393 | AA4: =if(V4 ="N2",ifna(vlookup(W4&"-"&X4,'Ref. VM'!A:B,2,0),"Custom"),if(V4 ="E2" , ifna(vlookup(W4&"-"&X4,'Ref. VM'!D:E,2,0),"Custom"),if(V4="N2D",ifna(vlookup(W4&"-"&X4,'Ref. VM'!G:H,2,0),"Custom"),if(V4="N4",ifna(vlookup(W4&"-"&X4,'Ref. VM'!J:K,2,0),"Custom"),0)))) -> Custom | AB4: =if( V4<>0,if(T4="Lift & Shift Prod",V4&"-"&AA4&" vCPUs-"&"CUD 3y",V4&"-"&AA4&" vCPUs"),0) -> N2D-Custom vCPUs-CUD 3y | AC4: =if( V4<>0,if(T4="Lift & Shift Prod",V4&"-"&AA4&" RAM-"&"CUD 3y",V4&"-"&AA4&" RAM"),0) -> N2D-Custom RAM-CUD 3y | AD4: =if(Y4=0,0,if( V4="N2D",if(T4="Lift & Shift Noprod","N2D-Extended custom memory","N2D-Extended custom memory-CUD 3y"),"N4-Extended custom memory")) -> 0 | AE4: =if(T4="Lift & Shift Prod",730,if(T4="Lift & Shift Noprod",Assumptions!$B$3,0)) -> 730 | AF4: =if( U4=0,0,if(Y4=0, ((vlookup(AB4,'SKU Pricing'!A:B,Assumptions!$B$2,0)*W4)+(vlookup(AC4,'SKU Pricing'!A:B,Assumptions!$B$2,0)*X4))*AE4,((vlookup(AB4,'SKU Pricing'!A:B,Assumptions!$B$2,0)*W4)+(vlookup(AC4,'SKU Pricing'!A:B,Assumptions!$B$2,0)*(W4*8))+(vlookup(AD4,'SKU Pricing'!A:B,Assumptions!$B$2,0)*(X4-(W4*8))))*AE4)) -> 27.908326 | AG4: =if(V4<>0, if(D4="Windows","Windows Server",if(D4="Linux",if( E4="Red Hat",if( W4<=8,"Red Hat Enterprise Linux 2-8", if(W4<128,"Red Hat Enterprise Linux 9-127","Red Hat Enterprise Linux 128")),0),0)),0) -> 0 | AH4: =ifna(vlookup(AG4,'SKU Pricing'!A:B,Assumptions!$B$2,0)*W4*AE4,0) -> 0 | AI4: =if(V4<>0, if(O4="T1","Regional",""),"") | AJ4: =if(V4<>0, if(T4="Lift & Shift Noprod",Assumptions!$B$9,if(V4=Assumptions!$B$6,Assumptions!$B$10,if(P4=1,Assumptions!$B$8,Assumptions!$B$7))),"") -> Balanced | AK4: =if( AJ4="",0,if(AI4="",AJ4,AJ4)) -> Balanced | AL4: =if(AJ4="Hyperdisk Balanced",Assumptions!$B$11,0) -> 0 | AM4: =if(AJ4="Hyperdisk Balanced",Assumptions!$B$12,0) -> 0 | AN4: =if(AK4=0,0,if(AJ4="Hyperdisk Balanced",vlookup(AK4&" provisioned space",'SKU Pricing'!A:B,Assumptions!$B$2,0)*Z4+vlookup(AK4&" provisioned IOPS",'SKU Pricing'!A:B,Assumptions!$B$2,0)*AL4*730+vlookup(AK4&" provisioned throughput",'SKU Pricing'!A:B,Assumptions!$B$2,0)*AM4*730,vlookup(AK4,'SKU Pricing'!A:B,Assumptions!$B$2,0)*Z4)) -> 625.588 | AO4: =AF4+AH4+AN4 -> 653.49633 | AP4: =if(V4<>0, "VM Manager",0) -> VM Manager | AQ4: =ifna(vlookup(AP4,'SKU Pricing'!A:B,Assumptions!$B$2,0)*AE4,0) -> 2.19 | AR4: 0
A5: DYO-2K8R2-SCANB | B5: =ifna(if(vlookup(A5,vOS!A:B,2,0)="","Unknown",vlookup(A5,vOS!A:B,2,0)),"Unknown") -> Microsoft Windows Server 2008 R2 (64-bit) | C5: =vlookup(B5,'OS Study'!A:D,2,0) -> 0 | D5: =vlookup(B5,'OS Study'!A:D,3,0) -> Windows | E5: =vlookup(B5,'OS Study'!A:D,4,0) -> Server | F5: =vlookup(B5,'OS Study'!A:E,5,0) -> 2008 R2 | G5: =IF(vlookup(A5,'RVtools V2.1'!A:J,4,0)="non",0,1) -> 0 | H5: =if(vlookup(A5,'RVtools V2.1'!A:K,11,0)="kube",1,0) -> 0 | I5: =if(H5=1, IF(COUNTIF(A5, "*MASTER*"), 1, 0),0) -> 0 | J5: =ifna(vlookup(A5,'Infra Study'!A:Q,17,0),0) -> 0 | K5: =IFERROR(__xludf.DUMMYFUNCTION("N(REGEXMATCH(VLOOKUP(A5, 'RVtools V2.1'!A:H, 8, 0), ""^Serveur de fichiers""))"),0.0) -> 0 | L5: =if(OR(C5=1,F5="2008 R2"),1,0) -> 1 | M5: =ifna(vlookup(A5,'RVtools V2.1'!A:I,8,0),"N/A") -> ScanBAC - RAL | N5: =IFERROR(__xludf.DUMMYFUNCTION("IF(REGEXMATCH(M5, ""(?i)"" & JOIN(""|"", SPLIT(""kalisil"", "" ""))), 1, 0)"),0.0) -> 0 | O5: =vlookup(A5,'RVtools V2.1'!A:H,7,0) -> N/A | P5: =if(vlookup(A5,'RVtools V2.1'!A:H,5,0)="oui",1,0) -> 0 | Q5: =ifna(vlookup(A5,vCPU!A:B,2,0),"Unknown") -> 2 | R5: =ifna(vlookup(A5,vMemory!A:C,3,0),"Unknown") -> 8 | S5: =ifna(vlookup(A5,vDisk!A:C,3,0),"Unknown") -> 270 | T5: {=IFS( L5=1, "No Lift & Shift", J5=1, XLOOKUP(A5, 'Infra Study'!A:A, 'Infra Study'!P:P), I5=1, "No Lift & Shift", H5=1, "GKE", K5=1, "GCNV", G5=1, "Lift & Shift Prod", TRUE, "Lift & Shift Noprod" )} -> No Lift & Shift | U5: =if(OR(T5="Lift & Shift Prod", T5="Lift & Shift Noprod"),1,0) -> 0 | V5: =if(T5="Lift & Shift Noprod",if( Y5=0,Assumptions!$B$5, Assumptions!$B$4),if(T5="Lift & Shift Prod",if(AND(N5=1,O5="T1"),Assumptions!$B$6,Assumptions!$B$4),0)) -> 0 | W5: =if(V5<>0,if(Q5="Unknown", Assumptions!$B$42,If(Q5>1,Q5,2)),0) -> 0 | X5: =if(V5<>0,if(R5="Unknown", Assumptions!$B$43,R5),0) -> 0 | Y5: =if(U5=1,if(X5/W5>8,1,0),0) -> 0 | Z5: =if(V5<>0,if( S5="Unknown", Assumptions!$B$44,S5),0) -> 0 | AA5: =if(V5 ="N2",ifna(vlookup(W5&"-"&X5,'Ref. VM'!A:B,2,0),"Custom"),if(V5 ="E2" , ifna(vlookup(W5&"-"&X5,'Ref. VM'!D:E,2,0),"Custom"),if(V5="N2D",ifna(vlookup(W5&"-"&X5,'Ref. VM'!G:H,2,0),"Custom"),if(V5="N4",ifna(vlookup(W5&"-"&X5,'Ref. VM'!J:K,2,0),"Custom"),0)))) -> 0 | AB5: =if( V5<>0,if(T5="Lift & Shift Prod",V5&"-"&AA5&" vCPUs-"&"CUD 3y",V5&"-"&AA5&" vCPUs"),0) -> 0 | AC5: =if( V5<>0,if(T5="Lift & Shift Prod",V5&"-"&AA5&" RAM-"&"CUD 3y",V5&"-"&AA5&" RAM"),0) -> 0 | AD5: =if(Y5=0,0,if( V5="N2D",if(T5="Lift & Shift Noprod","N2D-Extended custom memory","N2D-Extended custom memory-CUD 3y"),"N4-Extended custom memory")) -> 0 | AE5: =if(T5="Lift & Shift Prod",730,if(T5="Lift & Shift Noprod",Assumptions!$B$3,0)) -> 0 | AF5: =if( U5=0,0,if(Y5=0, ((vlookup(AB5,'SKU Pricing'!A:B,Assumptions!$B$2,0)*W5)+(vlookup(AC5,'SKU Pricing'!A:B,Assumptions!$B$2,0)*X5))*AE5,((vlookup(AB5,'SKU Pricing'!A:B,Assumptions!$B$2,0)*W5)+(vlookup(AC5,'SKU Pricing'!A:B,Assumptions!$B$2,0)*(W5*8))+(vlookup(AD5,'SKU Pricing'!A:B,Assumptions!$B$2,0)*(X5-(W5*8))))*AE5)) -> 0 | AG5: =if(V5<>0, if(D5="Windows","Windows Server",if(D5="Linux",if( E5="Red Hat",if( W5<=8,"Red Hat Enterprise Linux 2-8", if(W5<128,"Red Hat Enterprise Linux 9-127","Red Hat Enterprise Linux 128")),0),0)),0) -> 0 | AH5: =ifna(vlookup(AG5,'SKU Pricing'!A:B,Assumptions!$B$2,0)*W5*AE5,0) -> 0 | AI5: =if(V5<>0, if(O5="T1","Regional",""),"") | AJ5: =if(V5<>0, if(T5="Lift & Shift Noprod",Assumptions!$B$9,if(V5=Assumptions!$B$6,Assumptions!$B$10,if(P5=1,Assumptions!$B$8,Assumptions!$B$7))),"") | AK5: =if( AJ5="",0,if(AI5="",AJ5,AJ5)) -> 0 | AL5: =if(AJ5="Hyperdisk Balanced",Assumptions!$B$11,0) -> 0 | AM5: =if(AJ5="Hyperdisk Balanced",Assumptions!$B$12,0) -> 0 | AN5: =if(AK5=0,0,if(AJ5="Hyperdisk Balanced",vlookup(AK5&" provisioned space",'SKU Pricing'!A:B,Assumptions!$B$2,0)*Z5+vlookup(AK5&" provisioned IOPS",'SKU Pricing'!A:B,Assumptions!$B$2,0)*AL5*730+vlookup(AK5&" provisioned throughput",'SKU Pricing'!A:B,Assumptions!$B$2,0)*AM5*730,vlookup(AK5,'SKU Pricing'!A:B,Assumptions!$B$2,0)*Z5)) -> 0 | AO5: =AF5+AH5+AN5 -> 0 | AP5: =if(V5<>0, "VM Manager",0) -> 0 | AQ5: =ifna(vlookup(AP5,'SKU Pricing'!A:B,Assumptions!$B$2,0)*AE5,0) -> 0 | AR5: 0
A6: AURA-BDG01 | B6: =ifna(if(vlookup(A6,vOS!A:B,2,0)="","Unknown",vlookup(A6,vOS!A:B,2,0)),"Unknown") -> Microsoft Windows Server 2022 (64-bit) | C6: =vlookup(B6,'OS Study'!A:D,2,0) -> 0 | D6: =vlookup(B6,'OS Study'!A:D,3,0) -> Windows | E6: =vlookup(B6,'OS Study'!A:D,4,0) -> Server | F6: =vlookup(B6,'OS Study'!A:E,5,0) -> 2022 | G6: =IF(vlookup(A6,'RVtools V2.1'!A:J,4,0)="non",0,1) -> 1 | H6: =if(vlookup(A6,'RVtools V2.1'!A:K,11,0)="kube",1,0) -> 0 | I6: =if(H6=1, IF(COUNTIF(A6, "*MASTER*"), 1, 0),0) -> 0 | J6: =ifna(vlookup(A6,'Infra Study'!A:Q,17,0),0) -> 0 | K6: =IFERROR(__xludf.DUMMYFUNCTION("N(REGEXMATCH(VLOOKUP(A6, 'RVtools V2.1'!A:H, 8, 0), ""^Serveur de fichiers""))"),0.0) -> 0 | L6: =if(OR(C6=1,F6="2008 R2"),1,0) -> 0 | M6: =ifna(vlookup(A6,'RVtools V2.1'!A:I,8,0),"N/A") -> Badgeage - RAL | N6: =IFERROR(__xludf.DUMMYFUNCTION("IF(REGEXMATCH(M6, ""(?i)"" & JOIN(""|"", SPLIT(""kalisil"", "" ""))), 1, 0)"),0.0) -> 0 | O6: =vlookup(A6,'RVtools V2.1'!A:H,7,0) -> T3 | P6: =if(vlookup(A6,'RVtools V2.1'!A:H,5,0)="oui",1,0) -> 0 | Q6: =ifna(vlookup(A6,vCPU!A:B,2,0),"Unknown") -> 4 | R6: =ifna(vlookup(A6,vMemory!A:C,3,0),"Unknown") -> 8 | S6: =ifna(vlookup(A6,vDisk!A:C,3,0),"Unknown") -> 156 | T6: {=IFS( L6=1, "No Lift & Shift", J6=1, XLOOKUP(A6, 'Infra Study'!A:A, 'Infra Study'!P:P), I6=1, "No Lift & Shift", H6=1, "GKE", K6=1, "GCNV", G6=1, "Lift & Shift Prod", TRUE, "Lift & Shift Noprod" )} -> Lift & Shift Prod | U6: =if(OR(T6="Lift & Shift Prod", T6="Lift & Shift Noprod"),1,0) -> 1 | V6: =if(T6="Lift & Shift Noprod",if( Y6=0,Assumptions!$B$5, Assumptions!$B$4),if(T6="Lift & Shift Prod",if(AND(N6=1,O6="T1"),Assumptions!$B$6,Assumptions!$B$4),0)) -> N2D | W6: =if(V6<>0,if(Q6="Unknown", Assumptions!$B$42,If(Q6>1,Q6,2)),0) -> 4 | X6: =if(V6<>0,if(R6="Unknown", Assumptions!$B$43,R6),0) -> 8 | Y6: =if(U6=1,if(X6/W6>8,1,0),0) -> 0 | Z6: =if(V6<>0,if( S6="Unknown", Assumptions!$B$44,S6),0) -> 156 | AA6: =if(V6 ="N2",ifna(vlookup(W6&"-"&X6,'Ref. VM'!A:B,2,0),"Custom"),if(V6 ="E2" , ifna(vlookup(W6&"-"&X6,'Ref. VM'!D:E,2,0),"Custom"),if(V6="N2D",ifna(vlookup(W6&"-"&X6,'Ref. VM'!G:H,2,0),"Custom"),if(V6="N4",ifna(vlookup(W6&"-"&X6,'Ref. VM'!J:K,2,0),"Custom"),0)))) -> Custom | AB6: =if( V6<>0,if(T6="Lift & Shift Prod",V6&"-"&AA6&" vCPUs-"&"CUD 3y",V6&"-"&AA6&" vCPUs"),0) -> N2D-Custom vCPUs-CUD 3y | AC6: =if( V6<>0,if(T6="Lift & Shift Prod",V6&"-"&AA6&" RAM-"&"CUD 3y",V6&"-"&AA6&" RAM"),0) -> N2D-Custom RAM-CUD 3y | AD6: =if(Y6=0,0,if( V6="N2D",if(T6="Lift & Shift Noprod","N2D-Extended custom memory","N2D-Extended custom memory-CUD 3y"),"N4-Extended custom memory")) -> 0 | AE6: =if(T6="Lift & Shift Prod",730,if(T6="Lift & Shift Noprod",Assumptions!$B$3,0)) -> 730 | AF6: =if( U6=0,0,if(Y6=0, ((vlookup(AB6,'SKU Pricing'!A:B,Assumptions!$B$2,0)*W6)+(vlookup(AC6,'SKU Pricing'!A:B,Assumptions!$B$2,0)*X6))*AE6,((vlookup(AB6,'SKU Pricing'!A:B,Assumptions!$B$2,0)*W6)+(vlookup(AC6,'SKU Pricing'!A:B,Assumptions!$B$2,0)*(W6*8))+(vlookup(AD6,'SKU Pricing'!A:B,Assumptions!$B$2,0)*(X6-(W6*8))))*AE6)) -> 55.816653 | AG6: =if(V6<>0, if(D6="Windows","Windows Server",if(D6="Linux",if( E6="Red Hat",if( W6<=8,"Red Hat Enterprise Linux 2-8", if(W6<128,"Red Hat Enterprise Linux 9-127","Red Hat Enterprise Linux 128")),0),0)),0) -> Windows Server | AH6: =ifna(vlookup(AG6,'SKU Pricing'!A:B,Assumptions!$B$2,0)*W6*AE6,0) -> 134.32 | AI6: =if(V6<>0, if(O6="T1","Regional",""),"") | AJ6: =if(V6<>0, if(T6="Lift & Shift Noprod",Assumptions!$B$9,if(V6=Assumptions!$B$6,Assumptions!$B$10,if(P6=1,Assumptions!$B$8,Assumptions!$B$7))),"") -> Balanced | AK6: =if( AJ6="",0,if(AI6="",AJ6,AJ6)) -> Balanced | AL6: =if(AJ6="Hyperdisk Balanced",Assumptions!$B$11,0) -> 0 | AM6: =if(AJ6="Hyperdisk Balanced",Assumptions!$B$12,0) -> 0 | AN6: =if(AK6=0,0,if(AJ6="Hyperdisk Balanced",vlookup(AK6&" provisioned space",'SKU Pricing'!A:B,Assumptions!$B$2,0)*Z6+vlookup(AK6&" provisioned IOPS",'SKU Pricing'!A:B,Assumptions!$B$2,0)*AL6*730+vlookup(AK6&" provisioned throughput",'SKU Pricing'!A:B,Assumptions!$B$2,0)*AM6*730,vlookup(AK6,'SKU Pricing'!A:B,Assumptions!$B$2,0)*Z6)) -> 18.096 | AO6: =AF6+AH6+AN6 -> 208.23265 | AP6: =if(V6<>0, "VM Manager",0) -> VM Manager | AQ6: =ifna(vlookup(AP6,'SKU Pricing'!A:B,Assumptions!$B$2,0)*AE6,0) -> 2.19 | AR6: 0
A7: ORI-COMPTA01 | B7: =ifna(if(vlookup(A7,vOS!A:B,2,0)="","Unknown",vlookup(A7,vOS!A:B,2,0)),"Unknown") -> Microsoft Windows Server 2022 (64-bit) | C7: =vlookup(B7,'OS Study'!A:D,2,0) -> 0 | D7: =vlookup(B7,'OS Study'!A:D,3,0) -> Windows | E7: =vlookup(B7,'OS Study'!A:D,4,0) -> Server | F7: =vlookup(B7,'OS Study'!A:E,5,0) -> 2022 | G7: =IF(vlookup(A7,'RVtools V2.1'!A:J,4,0)="non",0,1) -> 1 | H7: =if(vlookup(A7,'RVtools V2.1'!A:K,11,0)="kube",1,0) -> 0 | I7: =if(H7=1, IF(COUNTIF(A7, "*MASTER*"), 1, 0),0) -> 0 | J7: =ifna(vlookup(A7,'Infra Study'!A:Q,17,0),0) -> 0 | K7: =IFERROR(__xludf.DUMMYFUNCTION("N(REGEXMATCH(VLOOKUP(A7, 'RVtools V2.1'!A:H, 8, 0), ""^Serveur de fichiers""))"),0.0) -> 0 | L7: =if(OR(C7=1,F7="2008 R2"),1,0) -> 0 | M7: =ifna(vlookup(A7,'RVtools V2.1'!A:I,8,0),"N/A") -> Serveur Compta Oriade | N7: =IFERROR(__xludf.DUMMYFUNCTION("IF(REGEXMATCH(M7, ""(?i)"" & JOIN(""|"", SPLIT(""kalisil"", "" ""))), 1, 0)"),0.0) -> 0 | O7: =vlookup(A7,'RVtools V2.1'!A:H,7,0) -> T1 | P7: =if(vlookup(A7,'RVtools V2.1'!A:H,5,0)="oui",1,0) -> 1 | Q7: =ifna(vlookup(A7,vCPU!A:B,2,0),"Unknown") -> 2 | R7: =ifna(vlookup(A7,vMemory!A:C,3,0),"Unknown") -> 8 | S7: =ifna(vlookup(A7,vDisk!A:C,3,0),"Unknown") -> 58 | T7: {=IFS( L7=1, "No Lift & Shift", J7=1, XLOOKUP(A7, 'Infra Study'!A:A, 'Infra Study'!P:P), I7=1, "No Lift & Shift", H7=1, "GKE", K7=1, "GCNV", G7=1, "Lift & Shift Prod", TRUE, "Lift & Shift Noprod" )} -> Lift & Shift Prod | U7: =if(OR(T7="Lift & Shift Prod", T7="Lift & Shift Noprod"),1,0) -> 1 | V7: =if(T7="Lift & Shift Noprod",if( Y7=0,Assumptions!$B$5, Assumptions!$B$4),if(T7="Lift & Shift Prod",if(AND(N7=1,O7="T1"),Assumptions!$B$6,Assumptions!$B$4),0)) -> N2D | W7: =if(V7<>0,if(Q7="Unknown", Assumptions!$B$42,If(Q7>1,Q7,2)),0) -> 2 | X7: =if(V7<>0,if(R7="Unknown", Assumptions!$B$43,R7),0) -> 8 | Y7: =if(U7=1,if(X7/W7>8,1,0),0) -> 0 | Z7: =if(V7<>0,if( S7="Unknown", Assumptions!$B$44,S7),0) -> 58 | AA7: =if(V7 ="N2",ifna(vlookup(W7&"-"&X7,'Ref. VM'!A:B,2,0),"Custom"),if(V7 ="E2" , ifna(vlookup(W7&"-"&X7,'Ref. VM'!D:E,2,0),"Custom"),if(V7="N2D",ifna(vlookup(W7&"-"&X7,'Ref. VM'!G:H,2,0),"Custom"),if(V7="N4",ifna(vlookup(W7&"-"&X7,'Ref. VM'!J:K,2,0),"Custom"),0)))) -> Custom | AB7: =if( V7<>0,if(T7="Lift & Shift Prod",V7&"-"&AA7&" vCPUs-"&"CUD 3y",V7&"-"&AA7&" vCPUs"),0) -> N2D-Custom vCPUs-CUD 3y | AC7: =if( V7<>0,if(T7="Lift & Shift Prod",V7&"-"&AA7&" RAM-"&"CUD 3y",V7&"-"&AA7&" RAM"),0) -> N2D-Custom RAM-CUD 3y | AD7: =if(Y7=0,0,if( V7="N2D",if(T7="Lift & Shift Noprod","N2D-Extended custom memory","N2D-Extended custom memory-CUD 3y"),"N4-Extended custom memory")) -> 0 | AE7: =if(T7="Lift & Shift Prod",730,if(T7="Lift & Shift Noprod",Assumptions!$B$3,0)) -> 730 | AF7: =if( U7=0,0,if(Y7=0, ((vlookup(AB7,'SKU Pricing'!A:B,Assumptions!$B$2,0)*W7)+(vlookup(AC7,'SKU Pricing'!A:B,Assumptions!$B$2,0)*X7))*AE7,((vlookup(AB7,'SKU Pricing'!A:B,Assumptions!$B$2,0)*W7)+(vlookup(AC7,'SKU Pricing'!A:B,Assumptions!$B$2,0)*(W7*8))+(vlookup(AD7,'SKU Pricing'!A:B,Assumptions!$B$2,0)*(X7-(W7*8))))*AE7)) -> 33.808659 | AG7: =if(V7<>0, if(D7="Windows","Windows Server",if(D7="Linux",if( E7="Red Hat",if( W7<=8,"Red Hat Enterprise Linux 2-8", if(W7<128,"Red Hat Enterprise Linux 9-127","Red Hat Enterprise Linux 128")),0),0)),0) -> Windows Server | AH7: =ifna(vlookup(AG7,'SKU Pricing'!A:B,Assumptions!$B$2,0)*W7*AE7,0) -> 67.16 | AI7: =if(V7<>0, if(O7="T1","Regional",""),"") -> Regional | AJ7: =if(V7<>0, if(T7="Lift & Shift Noprod",Assumptions!$B$9,if(V7=Assumptions!$B$6,Assumptions!$B$10,if(P7=1,Assumptions!$B$8,Assumptions!$B$7))),"") -> SSD | AK7: =if( AJ7="",0,if(AI7="",AJ7,AJ7)) -> SSD | AL7: =if(AJ7="Hyperdisk Balanced",Assumptions!$B$11,0) -> 0 | AM7: =if(AJ7="Hyperdisk Balanced",Assumptions!$B$12,0) -> 0 | AN7: =if(AK7=0,0,if(AJ7="Hyperdisk Balanced",vlookup(AK7&" provisioned space",'SKU Pricing'!A:B,Assumptions!$B$2,0)*Z7+vlookup(AK7&" provisioned IOPS",'SKU Pricing'!A:B,Assumptions!$B$2,0)*AL7*730+vlookup(AK7&" provisioned throughput",'SKU Pricing'!A:B,Assumptions!$B$2,0)*AM7*730,vlookup(AK7,'SKU Pricing'!A:B,Assumptions!$B$2,0)*Z7)) -> 11.426 | AO7: =AF7+AH7+AN7 -> 112.39466 | AP7: =if(V7<>0, "VM Manager",0) -> VM Manager | AQ7: =ifna(vlookup(AP7,'SKU Pricing'!A:B,Assumptions!$B$2,0)*AE7,0) -> 2.19 | AR7: 0
A8: ORI-SRV-INFEC | B8: =ifna(if(vlookup(A8,vOS!A:B,2,0)="","Unknown",vlookup(A8,vOS!A:B,2,0)),"Unknown") -> Microsoft Windows Server 2012 (64-bit) | C8: =vlookup(B8,'OS Study'!A:D,2,0) -> 0 | D8: =vlookup(B8,'OS Study'!A:D,3,0) -> Windows | E8: =vlookup(B8,'OS Study'!A:D,4,0) -> Server | F8: =vlookup(B8,'OS Study'!A:E,5,0) -> 2012 | G8: =IF(vlookup(A8,'RVtools V2.1'!A:J,4,0)="non",0,1) -> 0 | H8: =if(vlookup(A8,'RVtools V2.1'!A:K,11,0)="kube",1,0) -> 0 | I8: =if(H8=1, IF(COUNTIF(A8, "*MASTER*"), 1, 0),0) -> 0 | J8: =ifna(vlookup(A8,'Infra Study'!A:Q,17,0),0) -> 0 | K8: =IFERROR(__xludf.DUMMYFUNCTION("N(REGEXMATCH(VLOOKUP(A8, 'RVtools V2.1'!A:H, 8, 0), ""^Serveur de fichiers""))"),0.0) -> 0 | L8: =if(OR(C8=1,F8="2008 R2"),1,0) -> 0 | M8: =ifna(vlookup(A8,'RVtools V2.1'!A:I,8,0),"N/A") -> Infectio - ALI | N8: =IFERROR(__xludf.DUMMYFUNCTION("IF(REGEXMATCH(M8, ""(?i)"" & JOIN(""|"", SPLIT(""kalisil"", "" ""))), 1, 0)"),0.0) -> 0 | O8: =vlookup(A8,'RVtools V2.1'!A:H,7,0) -> N/A | P8: =if(vlookup(A8,'RVtools V2.1'!A:H,5,0)="oui",1,0) -> 0 | Q8: =ifna(vlookup(A8,vCPU!A:B,2,0),"Unknown") -> 2 | R8: =ifna(vlookup(A8,vMemory!A:C,3,0),"Unknown") -> 8 | S8: =ifna(vlookup(A8,vDisk!A:C,3,0),"Unknown") -> 237 | T8: {=IFS( L8=1, "No Lift & Shift", J8=1, XLOOKUP(A8, 'Infra Study'!A:A, 'Infra Study'!P:P), I8=1, "No Lift & Shift", H8=1, "GKE", K8=1, "GCNV", G8=1, "Lift & Shift Prod", TRUE, "Lift & Shift Noprod" )} -> Lift & Shift Noprod | U8: =if(OR(T8="Lift & Shift Prod", T8="Lift & Shift Noprod"),1,0) -> 1 | V8: =if(T8="Lift & Shift Noprod",if( Y8=0,Assumptions!$B$5, Assumptions!$B$4),if(T8="Lift & Shift Prod",if(AND(N8=1,O8="T1"),Assumptions!$B$6,Assumptions!$B$4),0)) -> E2 | W8: =if(V8<>0,if(Q8="Unknown", Assumptions!$B$42,If(Q8>1,Q8,2)),0) -> 2 | X8: =if(V8<>0,if(R8="Unknown", Assumptions!$B$43,R8),0) -> 8 | Y8: =if(U8=1,if(X8/W8>8,1,0),0) -> 0 | Z8: =if(V8<>0,if( S8="Unknown", Assumptions!$B$44,S8),0) -> 237 | AA8: =if(V8 ="N2",ifna(vlookup(W8&"-"&X8,'Ref. VM'!A:B,2,0),"Custom"),if(V8 ="E2" , ifna(vlookup(W8&"-"&X8,'Ref. VM'!D:E,2,0),"Custom"),if(V8="N2D",ifna(vlookup(W8&"-"&X8,'Ref. VM'!G:H,2,0),"Custom"),if(V8="N4",ifna(vlookup(W8&"-"&X8,'Ref. VM'!J:K,2,0),"Custom"),0)))) -> Custom | AB8: =if( V8<>0,if(T8="Lift & Shift Prod",V8&"-"&AA8&" vCPUs-"&"CUD 3y",V8&"-"&AA8&" vCPUs"),0) -> E2-Custom vCPUs | AC8: =if( V8<>0,if(T8="Lift & Shift Prod",V8&"-"&AA8&" RAM-"&"CUD 3y",V8&"-"&AA8&" RAM"),0) -> E2-Custom RAM | AD8: =if(Y8=0,0,if( V8="N2D",if(T8="Lift & Shift Noprod","N2D-Extended custom memory","N2D-Extended custom memory-CUD 3y"),"N4-Extended custom memory")) -> 0 | AE8: =if(T8="Lift & Shift Prod",730,if(T8="Lift & Shift Noprod",Assumptions!$B$3,0)) -> 270 | AF8: =if( U8=0,0,if(Y8=0, ((vlookup(AB8,'SKU Pricing'!A:B,Assumptions!$B$2,0)*W8)+(vlookup(AC8,'SKU Pricing'!A:B,Assumptions!$B$2,0)*X8))*AE8,((vlookup(AB8,'SKU Pricing'!A:B,Assumptions!$B$2,0)*W8)+(vlookup(AC8,'SKU Pricing'!A:B,Assumptions!$B$2,0)*(W8*8))+(vlookup(AD8,'SKU Pricing'!A:B,Assumptions!$B$2,0)*(X8-(W8*8))))*AE8)) -> 22.037022 | AG8: =if(V8<>0, if(D8="Windows","Windows Server",if(D8="Linux",if( E8="Red Hat",if( W8<=8,"Red Hat Enterprise Linux 2-8", if(W8<128,"Red Hat Enterprise Linux 9-127","Red Hat Enterprise Linux 128")),0),0)),0) -> Windows Server | AH8: =ifna(vlookup(AG8,'SKU Pricing'!A:B,Assumptions!$B$2,0)*W8*AE8,0) -> 24.84 | AI8: =if(V8<>0, if(O8="T1","Regional",""),"") | AJ8: =if(V8<>0, if(T8="Lift & Shift Noprod",Assumptions!$B$9,if(V8=Assumptions!$B$6,Assumptions!$B$10,if(P8=1,Assumptions!$B$8,Assumptions!$B$7))),"") -> Balanced | AK8: =if( AJ8="",0,if(AI8="",AJ8,AJ8)) -> Balanced | AL8: =if(AJ8="Hyperdisk Balanced",Assumptions!$B$11,0) -> 0 | AM8: =if(AJ8="Hyperdisk Balanced",Assumptions!$B$12,0) -> 0 | AN8: =if(AK8=0,0,if(AJ8="Hyperdisk Balanced",vlookup(AK8&" provisioned space",'SKU Pricing'!A:B,Assumptions!$B$2,0)*Z8+vlookup(AK8&" provisioned IOPS",'SKU Pricing'!A:B,Assumptions!$B$2,0)*AL8*730+vlookup(AK8&" provisioned throughput",'SKU Pricing'!A:B,Assumptions!$B$2,0)*AM8*730,vlookup(AK8,'SKU Pricing'!A:B,Assumptions!$B$2,0)*Z8)) -> 27.492 | AO8: =AF8+AH8+AN8 -> 74.369022 | AP8: =if(V8<>0, "VM Manager",0) -> VM Manager | AQ8: =ifna(vlookup(AP8,'SKU Pricing'!A:B,Assumptions!$B$2,0)*AE8,0) -> 0.81 | AR8: 0
A9: VMRDP | B9: =ifna(if(vlookup(A9,vOS!A:B,2,0)="","Unknown",vlookup(A9,vOS!A:B,2,0)),"Unknown") -> Microsoft Windows Server 2012 (64-bit) | C9: =vlookup(B9,'OS Study'!A:D,2,0) -> 0 | D9: =vlookup(B9,'OS Study'!A:D,3,0) -> Windows | E9: =vlookup(B9,'OS Study'!A:D,4,0) -> Server | F9: =vlookup(B9,'OS Study'!A:E,5,0) -> 2012 | G9: =IF(vlookup(A9,'RVtools V2.1'!A:J,4,0)="non",0,1) -> 1 | H9: =if(vlookup(A9,'RVtools V2.1'!A:K,11,0)="kube",1,0) -> 0 | I9: =if(H9=1, IF(COUNTIF(A9, "*MASTER*"), 1, 0),0) -> 0 | J9: =ifna(vlookup(A9,'Infra Study'!A:Q,17,0),0) -> 0 | K9: =IFERROR(__xludf.DUMMYFUNCTION("N(REGEXMATCH(VLOOKUP(A9, 'RVtools V2.1'!A:H, 8, 0), ""^Serveur de fichiers""))"),0.0) -> 0 | L9: =if(OR(C9=1,F9="2008 R2"),1,0) -> 0 | M9: =ifna(vlookup(A9,'RVtools V2.1'!A:I,8,0),"N/A") -> Infra - TSE | N9: =IFERROR(__xludf.DUMMYFUNCTION("IF(REGEXMATCH(M9, ""(?i)"" & JOIN(""|"", SPLIT(""kalisil"", "" ""))), 1, 0)"),0.0) -> 0 | O9: =vlookup(A9,'RVtools V2.1'!A:H,7,0) -> T2 | P9: =if(vlookup(A9,'RVtools V2.1'!A:H,5,0)="oui",1,0) -> 1 | Q9: =ifna(vlookup(A9,vCPU!A:B,2,0),"Unknown") -> 4 | R9: =ifna(vlookup(A9,vMemory!A:C,3,0),"Unknown") -> 16 | S9: =ifna(vlookup(A9,vDisk!A:C,3,0),"Unknown") -> 199 | T9: {=IFS( L9=1, "No Lift & Shift", J9=1, XLOOKUP(A9, 'Infra Study'!A:A, 'Infra Study'!P:P), I9=1, "No Lift & Shift", H9=1, "GKE", K9=1, "GCNV", G9=1, "Lift & Shift Prod", TRUE, "Lift & Shift Noprod" )} -> Lift & Shift Prod | U9: =if(OR(T9="Lift & Shift Prod", T9="Lift & Shift Noprod"),1,0) -> 1 | V9: =if(T9="Lift & Shift Noprod",if( Y9=0,Assumptions!$B$5, Assumptions!$B$4),if(T9="Lift & Shift Prod",if(AND(N9=1,O9="T1"),Assumptions!$B$6,Assumptions!$B$4),0)) -> N2D | W9: =if(V9<>0,if(Q9="Unknown", Assumptions!$B$42,If(Q9>1,Q9,2)),0) -> 4 | X9: =if(V9<>0,if(R9="Unknown", Assumptions!$B$43,R9),0) -> 16 | Y9: =if(U9=1,if(X9/W9>8,1,0),0) -> 0 | Z9: =if(V9<>0,if( S9="Unknown", Assumptions!$B$44,S9),0) -> 199 | AA9: =if(V9 ="N2",ifna(vlookup(W9&"-"&X9,'Ref. VM'!A:B,2,0),"Custom"),if(V9 ="E2" , ifna(vlookup(W9&"-"&X9,'Ref. VM'!D:E,2,0),"Custom"),if(V9="N2D",ifna(vlookup(W9&"-"&X9,'Ref. VM'!G:H,2,0),"Custom"),if(V9="N4",ifna(vlookup(W9&"-"&X9,'Ref. VM'!J:K,2,0),"Custom"),0)))) -> Predefined | AB9: =if( V9<>0,if(T9="Lift & Shift Prod",V9&"-"&AA9&" vCPUs-"&"CUD 3y",V9&"-"&AA9&" vCPUs"),0) -> N2D-Predefined vCPUs-CUD 3y | AC9: =if( V9<>0,if(T9="Lift & Shift Prod",V9&"-"&AA9&" RAM-"&"CUD 3y",V9&"-"&AA9&" RAM"),0) -> N2D-Predefined RAM-CUD 3y | AD9: =if(Y9=0,0,if( V9="N2D",if(T9="Lift & Shift Noprod","N2D-Extended custom memory","N2D-Extended custom memory-CUD 3y"),"N4-Extended custom memory")) -> 0 | AE9: =if(T9="Lift & Shift Prod",730,if(T9="Lift & Shift Noprod",Assumptions!$B$3,0)) -> 730 | AF9: =if( U9=0,0,if(Y9=0, ((vlookup(AB9,'SKU Pricing'!A:B,Assumptions!$B$2,0)*W9)+(vlookup(AC9,'SKU Pricing'!A:B,Assumptions!$B$2,0)*X9))*AE9,((vlookup(AB9,'SKU Pricing'!A:B,Assumptions!$B$2,0)*W9)+(vlookup(AC9,'SKU Pricing'!A:B,Assumptions!$B$2,0)*(W9*8))+(vlookup(AD9,'SKU Pricing'!A:B,Assumptions!$B$2,0)*(X9-(W9*8))))*AE9)) -> 64.397446 | AG9: =if(V9<>0, if(D9="Windows","Windows Server",if(D9="Linux",if( E9="Red Hat",if( W9<=8,"Red Hat Enterprise Linux 2-8", if(W9<128,"Red Hat Enterprise Linux 9-127","Red Hat Enterprise Linux 128")),0),0)),0) -> Windows Server | AH9: =ifna(vlookup(AG9,'SKU Pricing'!A:B,Assumptions!$B$2,0)*W9*AE9,0) -> 134.32 | AI9: =if(V9<>0, if(O9="T1","Regional",""),"") | AJ9: =if(V9<>0, if(T9="Lift & Shift Noprod",Assumptions!$B$9,if(V9=Assumptions!$B$6,Assumptions!$B$10,if(P9=1,Assumptions!$B$8,Assumptions!$B$7))),"") -> SSD | AK9: =if( AJ9="",0,if(AI9="",AJ9,AJ9)) -> SSD | AL9: =if(AJ9="Hyperdisk Balanced",Assumptions!$B$11,0) -> 0 | AM9: =if(AJ9="Hyperdisk Balanced",Assumptions!$B$12,0) -> 0 | AN9: =if(AK9=0,0,if(AJ9="Hyperdisk Balanced",vlookup(AK9&" provisioned space",'SKU Pricing'!A:B,Assumptions!$B$2,0)*Z9+vlookup(AK9&" provisioned IOPS",'SKU Pricing'!A:B,Assumptions!$B$2,0)*AL9*730+vlookup(AK9&" provisioned throughput",'SKU Pricing'!A:B,Assumptions!$B$2,0)*AM9*730,vlookup(AK9,'SKU Pricing'!A:B,Assumptions!$B$2,0)*Z9)) -> 39.203 | AO9: =AF9+AH9+AN9 -> 237.92045 | AP9: =if(V9<>0, "VM Manager",0) -> VM Manager | AQ9: =ifna(vlookup(AP9,'SKU Pricing'!A:B,Assumptions!$B$2,0)*AE9,0) -> 2.19 | AR9: 0
A10: GLBM-QMATIC01 | B10: =ifna(if(vlookup(A10,vOS!A:B,2,0)="","Unknown",vlookup(A10,vOS!A:B,2,0)),"Unknown") -> Microsoft Windows Server 2019 (64-bit) | C10: =vlookup(B10,'OS Study'!A:D,2,0) -> 0 | D10: =vlookup(B10,'OS Study'!A:D,3,0) -> Windows | E10: =vlookup(B10,'OS Study'!A:D,4,0) -> Server | F10: =vlookup(B10,'OS Study'!A:E,5,0) -> 2019 | G10: =IF(vlookup(A10,'RVtools V2.1'!A:J,4,0)="non",0,1) -> 1 | H10: =if(vlookup(A10,'RVtools V2.1'!A:K,11,0)="kube",1,0) -> 0 | I10: =if(H10=1, IF(COUNTIF(A10, "*MASTER*"), 1, 0),0) -> 0 | J10: =ifna(vlookup(A10,'Infra Study'!A:Q,17,0),0) -> 0 | K10: =IFERROR(__xludf.DUMMYFUNCTION("N(REGEXMATCH(VLOOKUP(A10, 'RVtools V2.1'!A:H, 8, 0), ""^Serveur de fichiers""))"),0.0) -> 0 | L10: =if(OR(C10=1,F10="2008 R2"),1,0) -> 0 | M10: =ifna(vlookup(A10,'RVtools V2.1'!A:I,8,0),"N/A") -> VM AFFICHEUR GLBM | N10: =IFERROR(__xludf.DUMMYFUNCTION("IF(REGEXMATCH(M10, ""(?i)"" & JOIN(""|"", SPLIT(""kalisil"", "" ""))), 1, 0)"),0.0) -> 0 | O10: =vlookup(A10,'RVtools V2.1'!A:H,7,0) -> N/A | P10: =if(vlookup(A10,'RVtools V2.1'!A:H,5,0)="oui",1,0) -> 0 | Q10: =ifna(vlookup(A10,vCPU!A:B,2,0),"Unknown") -> 4 | R10: =ifna(vlookup(A10,vMemory!A:C,3,0),"Unknown") -> 16 | S10: =ifna(vlookup(A10,vDisk!A:C,3,0),"Unknown") -> 194 | T10: {=IFS( L10=1, "No Lift & Shift", J10=1, XLOOKUP(A10, 'Infra Study'!A:A, 'Infra Study'!P:P), I10=1, "No Lift & Shift", H10=1, "GKE", K10=1, "GCNV", G10=1, "Lift & Shift Prod", TRUE, "Lift & Shift Noprod" )} -> Lift & Shift Prod | U10: =if(OR(T10="Lift & Shift Prod", T10="Lift & Shift Noprod"),1,0) -> 1 | V10: =if(T10="Lift & Shift Noprod",if( Y10=0,Assumptions!$B$5, Assumptions!$B$4),if(T10="Lift & Shift Prod",if(AND(N10=1,O10="T1"),Assumptions!$B$6,Assumptions!$B$4),0)) -> N2D | W10: =if(V10<>0,if(Q10="Unknown", Assumptions!$B$42,If(Q10>1,Q10,2)),0) -> 4 | X10: =if(V10<>0,if(R10="Unknown", Assumptions!$B$43,R10),0) -> 16 | Y10: =if(U10=1,if(X10/W10>8,1,0),0) -> 0 | Z10: =if(V10<>0,if( S10="Unknown", Assumptions!$B$44,S10),0) -> 194 | AA10: =if(V10 ="N2",ifna(vlookup(W10&"-"&X10,'Ref. VM'!A:B,2,0),"Custom"),if(V10 ="E2" , ifna(vlookup(W10&"-"&X10,'Ref. VM'!D:E,2,0),"Custom"),if(V10="N2D",ifna(vlookup(W10&"-"&X10,'Ref. VM'!G:H,2,0),"Custom"),if(V10="N4",ifna(vlookup(W10&"-"&X10,'Ref. VM'!J:K,2,0),"Custom"),0)))) -> Predefined | AB10: =if( V10<>0,if(T10="Lift & Shift Prod",V10&"-"&AA10&" vCPUs-"&"CUD 3y",V10&"-"&AA10&" vCPUs"),0) -> N2D-Predefined vCPUs-CUD 3y | AC10: =if( V10<>0,if(T10="Lift & Shift Prod",V10&"-"&AA10&" RAM-"&"CUD 3y",V10&"-"&AA10&" RAM"),0) -> N2D-Predefined RAM-CUD 3y | AD10: =if(Y10=0,0,if( V10="N2D",if(T10="Lift & Shift Noprod","N2D-Extended custom memory","N2D-Extended custom memory-CUD 3y"),"N4-Extended custom memory")) -> 0 | AE10: =if(T10="Lift & Shift Prod",730,if(T10="Lift & Shift Noprod",Assumptions!$B$3,0)) -> 730 | AF10: =if( U10=0,0,if(Y10=0, ((vlookup(AB10,'SKU Pricing'!A:B,Assumptions!$B$2,0)*W10)+(vlookup(AC10,'SKU Pricing'!A:B,Assumptions!$B$2,0)*X10))*AE10,((vlookup(AB10,'SKU Pricing'!A:B,Assumptions!$B$2,0)*W10)+(vlookup(AC10,'SKU Pricing'!A:B,Assumptions!$B$2,0)*(W10*8))+(vlookup(AD10,'SKU Pricing'!A:B,Assumptions!$B$2,0)*(X10-(W10*8))))*AE10)) -> 64.397446 | AG10: =if(V10<>0, if(D10="Windows","Windows Server",if(D10="Linux",if( E10="Red Hat",if( W10<=8,"Red Hat Enterprise Linux 2-8", if(W10<128,"Red Hat Enterprise Linux 9-127","Red Hat Enterprise Linux 128")),0),0)),0) -> Windows Server | AH10: =ifna(vlookup(AG10,'SKU Pricing'!A:B,Assumptions!$B$2,0)*W10*AE10,0) -> 134.32 | AI10: =if(V10<>0, if(O10="T1","Regional",""),"") | AJ10: =if(V10<>0, if(T10="Lift & Shift Noprod",Assumptions!$B$9,if(V10=Assumptions!$B$6,Assumptions!$B$10,if(P10=1,Assumptions!$B$8,Assumptions!$B$7))),"") -> Balanced | AK10: =if( AJ10="",0,if(AI10="",AJ10,AJ10)) -> Balanced | AL10: =if(AJ10="Hyperdisk Balanced",Assumptions!$B$11,0) -> 0 | AM10: =if(AJ10="Hyperdisk Balanced",Assumptions!$B$12,0) -> 0 | AN10: =if(AK10=0,0,if(AJ10="Hyperdisk Balanced",vlookup(AK10&" provisioned space",'SKU Pricing'!A:B,Assumptions!$B$2,0)*Z10+vlookup(AK10&" provisioned IOPS",'SKU Pricing'!A:B,Assumptions!$B$2,0)*AL10*730+vlookup(AK10&" provisioned throughput",'SKU Pricing'!A:B,Assumptions!$B$2,0)*AM10*730,vlookup(AK10,'SKU Pricing'!A:B,Assumptions!$B$2,0)*Z10)) -> 22.504 | AO10: =AF10+AH10+AN10 -> 221.22145 | AP10: =if(V10<>0, "VM Manager",0) -> VM Manager | AQ10: =ifna(vlookup(AP10,'SKU Pricing'!A:B,Assumptions!$B$2,0)*AE10,0) -> 2.19 | AR10: 0
A11: AURA-QMATIC | B11: =ifna(if(vlookup(A11,vOS!A:B,2,0)="","Unknown",vlookup(A11,vOS!A:B,2,0)),"Unknown") -> Microsoft Windows Server 2019 (64-bit) | C11: =vlookup(B11,'OS Study'!A:D,2,0) -> 0 | D11: =vlookup(B11,'OS Study'!A:D,3,0) -> Windows | E11: =vlookup(B11,'OS Study'!A:D,4,0) -> Server | F11: =vlookup(B11,'OS Study'!A:E,5,0) -> 2019 | G11: =IF(vlookup(A11,'RVtools V2.1'!A:J,4,0)="non",0,1) -> 1 | H11: =if(vlookup(A11,'RVtools V2.1'!A:K,11,0)="kube",1,0) -> 0 | I11: =if(H11=1, IF(COUNTIF(A11, "*MASTER*"), 1, 0),0) -> 0 | J11: =ifna(vlookup(A11,'Infra Study'!A:Q,17,0),0) -> 0 | K11: =IFERROR(__xludf.DUMMYFUNCTION("N(REGEXMATCH(VLOOKUP(A11, 'RVtools V2.1'!A:H, 8, 0), ""^Serveur de fichiers""))"),0.0) -> 0 | L11: =if(OR(C11=1,F11="2008 R2"),1,0) -> 0 | M11: =ifna(vlookup(A11,'RVtools V2.1'!A:I,8,0),"N/A") -> VM AFFICHEUR UNILIANS | N11: =IFERROR(__xludf.DUMMYFUNCTION("IF(REGEXMATCH(M11, ""(?i)"" & JOIN(""|"", SPLIT(""kalisil"", "" ""))), 1, 0)"),0.0) -> 0 | O11: =vlookup(A11,'RVtools V2.1'!A:H,7,0) -> N/A | P11: =if(vlookup(A11,'RVtools V2.1'!A:H,5,0)="oui",1,0) -> 0 | Q11: =ifna(vlookup(A11,vCPU!A:B,2,0),"Unknown") -> 4 | R11: =ifna(vlookup(A11,vMemory!A:C,3,0),"Unknown") -> 16 | S11: =ifna(vlookup(A11,vDisk!A:C,3,0),"Unknown") -> 243 | T11: {=IFS( L11=1, "No Lift & Shift", J11=1, XLOOKUP(A11, 'Infra Study'!A:A, 'Infra Study'!P:P), I11=1, "No Lift & Shift", H11=1, "GKE", K11=1, "GCNV", G11=1, "Lift & Shift Prod", TRUE, "Lift & Shift Noprod" )} -> Lift & Shift Prod | U11: =if(OR(T11="Lift & Shift Prod", T11="Lift & Shift Noprod"),1,0) -> 1 | V11: =if(T11="Lift & Shift Noprod",if( Y11=0,Assumptions!$B$5, Assumptions!$B$4),if(T11="Lift & Shift Prod",if(AND(N11=1,O11="T1"),Assumptions!$B$6,Assumptions!$B$4),0)) -> N2D | W11: =if(V11<>0,if(Q11="Unknown", Assumptions!$B$42,If(Q11>1,Q11,2)),0) -> 4 | X11: =if(V11<>0,if(R11="Unknown", Assumptions!$B$43,R11),0) -> 16 | Y11: =if(U11=1,if(X11/W11>8,1,0),0) -> 0 | Z11: =if(V11<>0,if( S11="Unknown", Assumptions!$B$44,S11),0) -> 243 | AA11: =if(V11 ="N2",ifna(vlookup(W11&"-"&X11,'Ref. VM'!A:B,2,0),"Custom"),if(V11 ="E2" , ifna(vlookup(W11&"-"&X11,'Ref. VM'!D:E,2,0),"Custom"),if(V11="N2D",ifna(vlookup(W11&"-"&X11,'Ref. VM'!G:H,2,0),"Custom"),if(V11="N4",ifna(vlookup(W11&"-"&X11,'Ref. VM'!J:K,2,0),"Custom"),0)))) -> Predefined | AB11: =if( V11<>0,if(T11="Lift & Shift Prod",V11&"-"&AA11&" vCPUs-"&"CUD 3y",V11&"-"&AA11&" vCPUs"),0) -> N2D-Predefined vCPUs-CUD 3y | AC11: =if( V11<>0,if(T11="Lift & Shift Prod",V11&"-"&AA11&" RAM-"&"CUD 3y",V11&"-"&AA11&" RAM"),0) -> N2D-Predefined RAM-CUD 3y | AD11: =if(Y11=0,0,if( V11="N2D",if(T11="Lift & Shift Noprod","N2D-Extended custom memory","N2D-Extended custom memory-CUD 3y"),"N4-Extended custom memory")) -> 0 | AE11: =if(T11="Lift & Shift Prod",730,if(T11="Lift & Shift Noprod",Assumptions!$B$3,0)) -> 730 | AF11: =if( U11=0,0,if(Y11=0, ((vlookup(AB11,'SKU Pricing'!A:B,Assumptions!$B$2,0)*W11)+(vlookup(AC11,'SKU Pricing'!A:B,Assumptions!$B$2,0)*X11))*AE11,((vlookup(AB11,'SKU Pricing'!A:B,Assumptions!$B$2,0)*W11)+(vlookup(AC11,'SKU Pricing'!A:B,Assumptions!$B$2,0)*(W11*8))+(vlookup(AD11,'SKU Pricing'!A:B,Assumptions!$B$2,0)*(X11-(W11*8))))*AE11)) -> 64.397446 | AG11: =if(V11<>0, if(D11="Windows","Windows Server",if(D11="Linux",if( E11="Red Hat",if( W11<=8,"Red Hat Enterprise Linux 2-8", if(W11<128,"Red Hat Enterprise Linux 9-127","Red Hat Enterprise Linux 128")),0),0)),0) -> Windows Server | AH11: =ifna(vlookup(AG11,'SKU Pricing'!A:B,Assumptions!$B$2,0)*W11*AE11,0) -> 134.32 | AI11: =if(V11<>0, if(O11="T1","Regional",""),"") | AJ11: =if(V11<>0, if(T11="Lift & Shift Noprod",Assumptions!$B$9,if(V11=Assumptions!$B$6,Assumptions!$B$10,if(P11=1,Assumptions!$B$8,Assumptions!$B$7))),"") -> Balanced | AK11: =if( AJ11="",0,if(AI11="",AJ11,AJ11)) -> Balanced | AL11: =if(AJ11="Hyperdisk Balanced",Assumptions!$B$11,0) -> 0 | AM11: =if(AJ11="Hyperdisk Balanced",Assumptions!$B$12,0) -> 0 | AN11: =if(AK11=0,0,if(AJ11="Hyperdisk Balanced",vlookup(AK11&" provisioned space",'SKU Pricing'!A:B,Assumptions!$B$2,0)*Z11+vlookup(AK11&" provisioned IOPS",'SKU Pricing'!A:B,Assumptions!$B$2,0)*AL11*730+vlookup(AK11&" provisioned throughput",'SKU Pricing'!A:B,Assumptions!$B$2,0)*AM11*730,vlookup(AK11,'SKU Pricing'!A:B,Assumptions!$B$2,0)*Z11)) -> 28.188 | AO11: =AF11+AH11+AN11 -> 226.90545 | AP11: =if(V11<>0, "VM Manager",0) -> VM Manager | AQ11: =ifna(vlookup(AP11,'SKU Pricing'!A:B,Assumptions!$B$2,0)*AE11,0) -> 2.19 | AR11: 0
A12: ORI-ALERE01 | B12: =ifna(if(vlookup(A12,vOS!A:B,2,0)="","Unknown",vlookup(A12,vOS!A:B,2,0)),"Unknown") -> Microsoft Windows Server 2022 (64-bit) | C12: =vlookup(B12,'OS Study'!A:D,2,0) -> 0 | D12: =vlookup(B12,'OS Study'!A:D,3,0) -> Windows | E12: =vlookup(B12,'OS Study'!A:D,4,0) -> Server | F12: =vlookup(B12,'OS Study'!A:E,5,0) -> 2022 | G12: =IF(vlookup(A12,'RVtools V2.1'!A:J,4,0)="non",0,1) -> 1 | H12: =if(vlookup(A12,'RVtools V2.1'!A:K,11,0)="kube",1,0) -> 0 | I12: =if(H12=1, IF(COUNTIF(A12, "*MASTER*"), 1, 0),0) -> 0 | J12: =ifna(vlookup(A12,'Infra Study'!A:Q,17,0),0) -> 0 | K12: =IFERROR(__xludf.DUMMYFUNCTION("N(REGEXMATCH(VLOOKUP(A12, 'RVtools V2.1'!A:H, 8, 0), ""^Serveur de fichiers""))"),0.0) -> 0 | L12: =if(OR(C12=1,F12="2008 R2"),1,0) -> 0 | M12: =ifna(vlookup(A12,'RVtools V2.1'!A:I,8,0),"N/A") -> ALERE - ALI | N12: =IFERROR(__xludf.DUMMYFUNCTION("IF(REGEXMATCH(M12, ""(?i)"" & JOIN(""|"", SPLIT(""kalisil"", "" ""))), 1, 0)"),0.0) -> 0 | O12: =vlookup(A12,'RVtools V2.1'!A:H,7,0) -> T1 | P12: =if(vlookup(A12,'RVtools V2.1'!A:H,5,0)="oui",1,0) -> 1 | Q12: =ifna(vlookup(A12,vCPU!A:B,2,0),"Unknown") -> 2 | R12: =ifna(vlookup(A12,vMemory!A:C,3,0),"Unknown") -> 4 | S12: =ifna(vlookup(A12,vDisk!A:C,3,0),"Unknown") -> 149 | T12: {=IFS( L12=1, "No Lift & Shift", J12=1, XLOOKUP(A12, 'Infra Study'!A:A, 'Infra Study'!P:P), I12=1, "No Lift & Shift", H12=1, "GKE", K12=1, "GCNV", G12=1, "Lift & Shift Prod", TRUE, "Lift & Shift Noprod" )} -> Lift & Shift Prod | U12: =if(OR(T12="Lift & Shift Prod", T12="Lift & Shift Noprod"),1,0) -> 1 | V12: =if(T12="Lift & Shift Noprod",if( Y12=0,Assumptions!$B$5, Assumptions!$B$4),if(T12="Lift & Shift Prod",if(AND(N12=1,O12="T1"),Assumptions!$B$6,Assumptions!$B$4),0)) -> N2D | W12: =if(V12<>0,if(Q12="Unknown", Assumptions!$B$42,If(Q12>1,Q12,2)),0) -> 2 | X12: =if(V12<>0,if(R12="Unknown", Assumptions!$B$43,R12),0) -> 4 | Y12: =if(U12=1,if(X12/W12>8,1,0),0) -> 0 | Z12: =if(V12<>0,if( S12="Unknown", Assumptions!$B$44,S12),0) -> 149 | AA12: =if(V12 ="N2",ifna(vlookup(W12&"-"&X12,'Ref. VM'!A:B,2,0),"Custom"),if(V12 ="E2" , ifna(vlookup(W12&"-"&X12,'Ref. VM'!D:E,2,0),"Custom"),if(V12="N2D",ifna(vlookup(W12&"-"&X12,'Ref. VM'!G:H,2,0),"Custom"),if(V12="N4",ifna(vlookup(W12&"-"&X12,'Ref. VM'!J:K,2,0),"Custom"),0)))) -> Custom | AB12: =if( V12<>0,if(T12="Lift & Shift Prod",V12&"-"&AA12&" vCPUs-"&"CUD 3y",V12&"-"&AA12&" vCPUs"),0) -> N2D-Custom vCPUs-CUD 3y | AC12: =if( V12<>0,if(T12="Lift & Shift Prod",V12&"-"&AA12&" RAM-"&"CUD 3y",V12&"-"&AA12&" RAM"),0) -> N2D-Custom RAM-CUD 3y | AD12: =if(Y12=0,0,if( V12="N2D",if(T12="Lift & Shift Noprod","N2D-Extended custom memory","N2D-Extended custom memory-CUD 3y"),"N4-Extended custom memory")) -> 0 | AE12: =if(T12="Lift & Shift Prod",730,if(T12="Lift & Shift Noprod",Assumptions!$B$3,0)) -> 730 | AF12: =if( U12=0,0,if(Y12=0, ((vlookup(AB12,'SKU Pricing'!A:B,Assumptions!$B$2,0)*W12)+(vlookup(AC12,'SKU Pricing'!A:B,Assumptions!$B$2,0)*X12))*AE12,((vlookup(AB12,'SKU Pricing'!A:B,Assumptions!$B$2,0)*W12)+(vlookup(AC12,'SKU Pricing'!A:B,Assumptions!$B$2,0)*(W12*8))+(vlookup(AD12,'SKU Pricing'!A:B,Assumptions!$B$2,0)*(X12-(W12*8))))*AE12)) -> 27.908326 | AG12: =if(V12<>0, if(D12="Windows","Windows Server",if(D12="Linux",if( E12="Red Hat",if( W12<=8,"Red Hat Enterprise Linux 2-8", if(W12<128,"Red Hat Enterprise Linux 9-127","Red Hat Enterprise Linux 128")),0),0)),0) -> Windows Server | AH12: =ifna(vlookup(AG12,'SKU Pricing'!A:B,Assumptions!$B$2,0)*W12*AE12,0) -> 67.16 | AI12: =if(V12<>0, if(O12="T1","Regional",""),"") -> Regional | AJ12: =if(V12<>0, if(T12="Lift & Shift Noprod",Assumptions!$B$9,if(V12=Assumptions!$B$6,Assumptions!$B$10,if(P12=1,Assumptions!$B$8,Assumptions!$B$7))),"") -> SSD | AK12: =if( AJ12="",0,if(AI12="",AJ12,AJ12)) -> SSD | AL12: =if(AJ12="Hyperdisk Balanced",Assumptions!$B$11,0) -> 0 | AM12: =if(AJ12="Hyperdisk Balanced",Assumptions!$B$12,0) -> 0 | AN12: =if(AK12=0,0,if(AJ12="Hyperdisk Balanced",vlookup(AK12&" provisioned space",'SKU Pricing'!A:B,Assumptions!$B$2,0)*Z12+vlookup(AK12&" provisioned IOPS",'SKU Pricing'!A:B,Assumptions!$B$2,0)*AL12*730+vlookup(AK12&" provisioned throughput",'SKU Pricing'!A:B,Assumptions!$B$2,0)*AM12*730,vlookup(AK12,'SKU Pricing'!A:B,Assumptions!$B$2,0)*Z12)) -> 29.353 | AO12: =AF12+AH12+AN12 -> 124.42133 | AP12: =if(V12<>0, "VM Manager",0) -> VM Manager | AQ12: =ifna(vlookup(AP12,'SKU Pricing'!A:B,Assumptions!$B$2,0)*AE12,0) -> 2.19 | AR12: 0
A13: ORI-SRV-ALERE01 | B13: =ifna(if(vlookup(A13,vOS!A:B,2,0)="","Unknown",vlookup(A13,vOS!A:B,2,0)),"Unknown") -> Microsoft Windows Server 2008 R2 (64-bit) | C13: =vlookup(B13,'OS Study'!A:D,2,0) -> 0 | D13: =vlookup(B13,'OS Study'!A:D,3,0) -> Windows | E13: =vlookup(B13,'OS Study'!A:D,4,0) -> Server | F13: =vlookup(B13,'OS Study'!A:E,5,0) -> 2008 R2 | G13: =IF(vlookup(A13,'RVtools V2.1'!A:J,4,0)="non",0,1) -> 1 | H13: =if(vlookup(A13,'RVtools V2.1'!A:K,11,0)="kube",1,0) -> 0 | I13: =if(H13=1, IF(COUNTIF(A13, "*MASTER*"), 1, 0),0) -> 0 | J13: =ifna(vlookup(A13,'Infra Study'!A:Q,17,0),0) -> 0 | K13: =IFERROR(__xludf.DUMMYFUNCTION("N(REGEXMATCH(VLOOKUP(A13, 'RVtools V2.1'!A:H, 8, 0), ""^Serveur de fichiers""))"),0.0) -> 0 | L13: =if(OR(C13=1,F13="2008 R2"),1,0) -> 1 | M13: =ifna(vlookup(A13,'RVtools V2.1'!A:I,8,0),"N/A") -> ALERE - ALI | N13: =IFERROR(__xludf.DUMMYFUNCTION("IF(REGEXMATCH(M13, ""(?i)"" & JOIN(""|"", SPLIT(""kalisil"", "" ""))), 1, 0)"),0.0) -> 0 | O13: =vlookup(A13,'RVtools V2.1'!A:H,7,0) -> T1 | P13: =if(vlookup(A13,'RVtools V2.1'!A:H,5,0)="oui",1,0) -> 1 | Q13: =ifna(vlookup(A13,vCPU!A:B,2,0),"Unknown") -> 2 | R13: =ifna(vlookup(A13,vMemory!A:C,3,0),"Unknown") -> 8 | S13: =ifna(vlookup(A13,vDisk!A:C,3,0),"Unknown") -> 130 | T13: {=IFS( L13=1, "No Lift & Shift", J13=1, XLOOKUP(A13, 'Infra Study'!A:A, 'Infra Study'!P:P), I13=1, "No Lift & Shift", H13=1, "GKE", K13=1, "GCNV", G13=1, "Lift & Shift Prod", TRUE, "Lift & Shift Noprod" )} -> No Lift & Shift | U13: =if(OR(T13="Lift & Shift Prod", T13="Lift & Shift Noprod"),1,0) -> 0 | V13: =if(T13="Lift & Shift Noprod",if( Y13=0,Assumptions!$B$5, Assumptions!$B$4),if(T13="Lift & Shift Prod",if(AND(N13=1,O13="T1"),Assumptions!$B$6,Assumptions!$B$4),0)) -> 0 | W13: =if(V13<>0,if(Q13="Unknown", Assumptions!$B$42,If(Q13>1,Q13,2)),0) -> 0 | X13: =if(V13<>0,if(R13="Unknown", Assumptions!$B$43,R13),0) -> 0 | Y13: =if(U13=1,if(X13/W13>8,1,0),0) -> 0 | Z13: =if(V13<>0,if( S13="Unknown", Assumptions!$B$44,S13),0) -> 0 | AA13: =if(V13 ="N2",ifna(vlookup(W13&"-"&X13,'Ref. VM'!A:B,2,0),"Custom"),if(V13 ="E2" , ifna(vlookup(W13&"-"&X13,'Ref. VM'!D:E,2,0),"Custom"),if(V13="N2D",ifna(vlookup(W13&"-"&X13,'Ref. VM'!G:H,2,0),"Custom"),if(V13="N4",ifna(vlookup(W13&"-"&X13,'Ref. VM'!J:K,2,0),"Custom"),0)))) -> 0 | AB13: =if( V13<>0,if(T13="Lift & Shift Prod",V13&"-"&AA13&" vCPUs-"&"CUD 3y",V13&"-"&AA13&" vCPUs"),0) -> 0 | AC13: =if( V13<>0,if(T13="Lift & Shift Prod",V13&"-"&AA13&" RAM-"&"CUD 3y",V13&"-"&AA13&" RAM"),0) -> 0 | AD13: =if(Y13=0,0,if( V13="N2D",if(T13="Lift & Shift Noprod","N2D-Extended custom memory","N2D-Extended custom memory-CUD 3y"),"N4-Extended custom memory")) -> 0 | AE13: =if(T13="Lift & Shift Prod",730,if(T13="Lift & Shift Noprod",Assumptions!$B$3,0)) -> 0 | AF13: =if( U13=0,0,if(Y13=0, ((vlookup(AB13,'SKU Pricing'!A:B,Assumptions!$B$2,0)*W13)+(vlookup(AC13,'SKU Pricing'!A:B,Assumptions!$B$2,0)*X13))*AE13,((vlookup(AB13,'SKU Pricing'!A:B,Assumptions!$B$2,0)*W13)+(vlookup(AC13,'SKU Pricing'!A:B,Assumptions!$B$2,0)*(W13*8))+(vlookup(AD13,'SKU Pricing'!A:B,Assumptions!$B$2,0)*(X13-(W13*8))))*AE13)) -> 0 | AG13: =if(V13<>0, if(D13="Windows","Windows Server",if(D13="Linux",if( E13="Red Hat",if( W13<=8,"Red Hat Enterprise Linux 2-8", if(W13<128,"Red Hat Enterprise Linux 9-127","Red Hat Enterprise Linux 128")),0),0)),0) -> 0 | AH13: =ifna(vlookup(AG13,'SKU Pricing'!A:B,Assumptions!$B$2,0)*W13*AE13,0) -> 0 | AI13: =if(V13<>0, if(O13="T1","Regional",""),"") | AJ13: =if(V13<>0, if(T13="Lift & Shift Noprod",Assumptions!$B$9,if(V13=Assumptions!$B$6,Assumptions!$B$10,if(P13=1,Assumptions!$B$8,Assumptions!$B$7))),"") | AK13: =if( AJ13="",0,if(AI13="",AJ13,AJ13)) -> 0 | AL13: =if(AJ13="Hyperdisk Balanced",Assumptions!$B$11,0) -> 0 | AM13: =if(AJ13="Hyperdisk Balanced",Assumptions!$B$12,0) -> 0 | AN13: =if(AK13=0,0,if(AJ13="Hyperdisk Balanced",vlookup(AK13&" provisioned space",'SKU Pricing'!A:B,Assumptions!$B$2,0)*Z13+vlookup(AK13&" provisioned IOPS",'SKU Pricing'!A:B,Assumptions!$B$2,0)*AL13*730+vlookup(AK13&" provisioned throughput",'SKU Pricing'!A:B,Assumptions!$B$2,0)*AM13*730,vlookup(AK13,'SKU Pricing'!A:B,Assumptions!$B$2,0)*Z13)) -> 0 | AO13: =AF13+AH13+AN13 -> 0 | AP13: =if(V13<>0, "VM Manager",0) -> 0 | AQ13: =ifna(vlookup(AP13,'SKU Pricing'!A:B,Assumptions!$B$2,0)*AE13,0) -> 0 | AR13: 0
A14: UNI-CASTEL01 | B14: =ifna(if(vlookup(A14,vOS!A:B,2,0)="","Unknown",vlookup(A14,vOS!A:B,2,0)),"Unknown") -> Microsoft Windows 10 (64-bit) | C14: =vlookup(B14,'OS Study'!A:D,2,0) -> 0 | D14: =vlookup(B14,'OS Study'!A:D,3,0) -> Windows | E14: =vlookup(B14,'OS Study'!A:D,4,0) -> Workstation | F14: =vlookup(B14,'OS Study'!A:E,5,0) -> 10 | G14: =IF(vlookup(A14,'RVtools V2.1'!A:J,4,0)="non",0,1) -> 1 | H14: =if(vlookup(A14,'RVtools V2.1'!A:K,11,0)="kube",1,0) -> 0 | I14: =if(H14=1, IF(COUNTIF(A14, "*MASTER*"), 1, 0),0) -> 0 | J14: =ifna(vlookup(A14,'Infra Study'!A:Q,17,0),0) -> 1 | K14: =IFERROR(__xludf.DUMMYFUNCTION("N(REGEXMATCH(VLOOKUP(A14, 'RVtools V2.1'!A:H, 8, 0), ""^Serveur de fichiers""))"),0.0) -> 0 | L14: =if(OR(C14=1,F14="2008 R2"),1,0) -> 0 | M14: =ifna(vlookup(A14,'RVtools V2.1'!A:I,8,0),"N/A") -> Badgeage - RAL | N14: =IFERROR(__xludf.DUMMYFUNCTION("IF(REGEXMATCH(M14, ""(?i)"" & JOIN(""|"", SPLIT(""kalisil"", "" ""))), 1, 0)"),0.0) -> 0 | O14: =vlookup(A14,'RVtools V2.1'!A:H,7,0) -> T3 | P14: =if(vlookup(A14,'RVtools V2.1'!A:H,5,0)="oui",1,0) -> 0 | Q14: =ifna(vlookup(A14,vCPU!A:B,2,0),"Unknown") -> 4 | R14: =ifna(vlookup(A14,vMemory!A:C,3,0),"Unknown") -> 4 | S14: =ifna(vlookup(A14,vDisk!A:C,3,0),"Unknown") -> 120 | T14: {=IFS( L14=1, "No Lift & Shift", J14=1, XLOOKUP(A14, 'Infra Study'!A:A, 'Infra Study'!P:P), I14=1, "No Lift & Shift", H14=1, "GKE", K14=1, "GCNV", G14=1, "Lift & Shift Prod", TRUE, "Lift & Shift Noprod" )} -> Consolidation | U14: =if(OR(T14="Lift & Shift Prod", T14="Lift & Shift Noprod"),1,0) -> 0 | V14: =if(T14="Lift & Shift Noprod",if( Y14=0,Assumptions!$B$5, Assumptions!$B$4),if(T14="Lift & Shift Prod",if(AND(N14=1,O14="T1"),Assumptions!$B$6,Assumptions!$B$4),0)) -> 0 | W14: =if(V14<>0,if(Q14="Unknown", Assumptions!$B$42,If(Q14>1,Q14,2)),0) -> 0 | X14: =if(V14<>0,if(R14="Unknown", Assumptions!$B$43,R14),0) -> 0 | Y14: =if(U14=1,if(X14/W14>8,1,0),0) -> 0 | Z14: =if(V14<>0,if( S14="Unknown", Assumptions!$B$44,S14),0) -> 0 | AA14: =if(V14 ="N2",ifna(vlookup(W14&"-"&X14,'Ref. VM'!A:B,2,0),"Custom"),if(V14 ="E2" , ifna(vlookup(W14&"-"&X14,'Ref. VM'!D:E,2,0),"Custom"),if(V14="N2D",ifna(vlookup(W14&"-"&X14,'Ref. VM'!G:H,2,0),"Custom"),if(V14="N4",ifna(vlookup(W14&"-"&X14,'Ref. VM'!J:K,2,0),"Custom"),0)))) -> 0 | AB14: =if( V14<>0,if(T14="Lift & Shift Prod",V14&"-"&AA14&" vCPUs-"&"CUD 3y",V14&"-"&AA14&" vCPUs"),0) -> 0 | AC14: =if( V14<>0,if(T14="Lift & Shift Prod",V14&"-"&AA14&" RAM-"&"CUD 3y",V14&"-"&AA14&" RAM"),0) -> 0 | AD14: =if(Y14=0,0,if( V14="N2D",if(T14="Lift & Shift Noprod","N2D-Extended custom memory","N2D-Extended custom memory-CUD 3y"),"N4-Extended custom memory")) -> 0 | AE14: =if(T14="Lift & Shift Prod",730,if(T14="Lift & Shift Noprod",Assumptions!$B$3,0)) -> 0 | AF14: =if( U14=0,0,if(Y14=0, ((vlookup(AB14,'SKU Pricing'!A:B,Assumptions!$B$2,0)*W14)+(vlookup(AC14,'SKU Pricing'!A:B,Assumptions!$B$2,0)*X14))*AE14,((vlookup(AB14,'SKU Pricing'!A:B,Assumptions!$B$2,0)*W14)+(vlookup(AC14,'SKU Pricing'!A:B,Assumptions!$B$2,0)*(W14*8))+(vlookup(AD14,'SKU Pricing'!A:B,Assumptions!$B$2,0)*(X14-(W14*8))))*AE14)) -> 0 | AG14: =if(V14<>0, if(D14="Windows","Windows Server",if(D14="Linux",if( E14="Red Hat",if( W14<=8,"Red Hat Enterprise Linux 2-8", if(W14<128,"Red Hat Enterprise Linux 9-127","Red Hat Enterprise Linux 128")),0),0)),0) -> 0 | AH14: =ifna(vlookup(AG14,'SKU Pricing'!A:B,Assumptions!$B$2,0)*W14*AE14,0) -> 0 | AI14: =if(V14<>0, if(O14="T1","Regional",""),"") | AJ14: =if(V14<>0, if(T14="Lift & Shift Noprod",Assumptions!$B$9,if(V14=Assumptions!$B$6,Assumptions!$B$10,if(P14=1,Assumptions!$B$8,Assumptions!$B$7))),"") | AK14: =if( AJ14="",0,if(AI14="",AJ14,AJ14)) -> 0 | AL14: =if(AJ14="Hyperdisk Balanced",Assumptions!$B$11,0) -> 0 | AM14: =if(AJ14="Hyperdisk Balanced",Assumptions!$B$12,0) -> 0 | AN14: =if(AK14=0,0,if(AJ14="Hyperdisk Balanced",vlookup(AK14&" provisioned space",'SKU Pricing'!A:B,Assumptions!$B$2,0)*Z14+vlookup(AK14&" provisioned IOPS",'SKU Pricing'!A:B,Assumptions!$B$2,0)*AL14*730+vlookup(AK14&" provisioned throughput",'SKU Pricing'!A:B,Assumptions!$B$2,0)*AM14*730,vlookup(AK14,'SKU Pricing'!A:B,Assumptions!$B$2,0)*Z14)) -> 0 | AO14: =AF14+AH14+AN14 -> 0 | AP14: =if(V14<>0, "VM Manager",0) -> 0 | AQ14: =ifna(vlookup(AP14,'SKU Pricing'!A:B,Assumptions!$B$2,0)*AE14,0) -> 0 | AR14: 0
